{"level":"ERROR","location":"[On_message:1446] data_ws","message":"'NoneType' object cannot be interpreted as an integer","timestamp":"2024-09-09 12:08:57,487+0530","service":"FyersDataSocket","exception":"Traceback (most recent call last):\n  File \"C:\\Users\\USER\\AppData\\Local\\Programs\\Python\\Python312\\Lib\\site-packages\\fyers_apiv3\\FyersWebsocket\\data_ws.py\", line 1433, in On_message\n    self.OnMessage(message)\n  File \"c:\\Users\\USER\\AppData\\Local\\Temp\\1470bfdd-cfe0-4f5e-aeab-115567aeefc6_python_scripts.zip.fc6\\python_scripts\\fyerapi.py\", line 198, in onmessage\n    timestamp = datetime.fromtimestamp(message.get(\"exch_feed_time\"))\n                ^^^^^^^^^^^^^^^^^^^^^^^^^^^^^^^^^^^^^^^^^^^^^^^^^^^^^\nTypeError: 'NoneType' object cannot be interpreted as an integer","exception_name":"TypeError"}
{"level":"ERROR","location":"[On_message:1447] data_ws","message":"'NoneType' object cannot be interpreted as an integer","timestamp":"2024-09-09 12:08:57,501+0530","service":"FyersDataSocket"}
{"level":"ERROR","location":"[symbol_to_hsmtoken:126] data_ws","message":"cannot access local variable 'hsm_symbol' where it is not associated with a value","timestamp":"2024-09-09 12:08:59,273+0530","service":"FyersDataSocket","exception":"Traceback (most recent call last):\n  File \"C:\\Users\\USER\\AppData\\Local\\Programs\\Python\\Python312\\Lib\\site-packages\\fyers_apiv3\\FyersWebsocket\\data_ws.py\", line 115, in symbol_to_hsmtoken\n    datadict[hsm_symbol] = symbol\n             ^^^^^^^^^^\nUnboundLocalError: cannot access local variable 'hsm_symbol' where it is not associated with a value","exception_name":"UnboundLocalError"}
{"level":"ERROR","location":"[__symbol_conversion:1374] data_ws","message":"'NoneType' object is not subscriptable","timestamp":"2024-09-09 12:08:59,279+0530","service":"FyersDataSocket","exception":"Traceback (most recent call last):\n  File \"C:\\Users\\USER\\AppData\\Local\\Programs\\Python\\Python312\\Lib\\site-packages\\fyers_apiv3\\FyersWebsocket\\data_ws.py\", line 1333, in __symbol_conversion\n    if symbol_value[3] != \"\":\n       ~~~~~~~~~~~~^^^\nTypeError: 'NoneType' object is not subscriptable","exception_name":"TypeError"}
{"level":"ERROR","location":"[symbol_to_hsmtoken:126] data_ws","message":"cannot access local variable 'hsm_symbol' where it is not associated with a value","timestamp":"2024-09-09 12:40:56,568+0530","service":"FyersDataSocket","exception":"Traceback (most recent call last):\n  File \"C:\\Users\\USER\\AppData\\Local\\Programs\\Python\\Python312\\Lib\\site-packages\\fyers_apiv3\\FyersWebsocket\\data_ws.py\", line 115, in symbol_to_hsmtoken\n    datadict[hsm_symbol] = symbol\n             ^^^^^^^^^^\nUnboundLocalError: cannot access local variable 'hsm_symbol' where it is not associated with a value","exception_name":"UnboundLocalError"}
{"level":"ERROR","location":"[__symbol_conversion:1374] data_ws","message":"'NoneType' object is not subscriptable","timestamp":"2024-09-09 12:40:56,575+0530","service":"FyersDataSocket","exception":"Traceback (most recent call last):\n  File \"C:\\Users\\USER\\AppData\\Local\\Programs\\Python\\Python312\\Lib\\site-packages\\fyers_apiv3\\FyersWebsocket\\data_ws.py\", line 1333, in __symbol_conversion\n    if symbol_value[3] != \"\":\n       ~~~~~~~~~~~~^^^\nTypeError: 'NoneType' object is not subscriptable","exception_name":"TypeError"}
{"level":"ERROR","location":"[symbol_to_hsmtoken:126] data_ws","message":"cannot access local variable 'hsm_symbol' where it is not associated with a value","timestamp":"2024-09-09 12:53:49,432+0530","service":"FyersDataSocket","exception":"Traceback (most recent call last):\n  File \"C:\\Users\\USER\\AppData\\Local\\Programs\\Python\\Python312\\Lib\\site-packages\\fyers_apiv3\\FyersWebsocket\\data_ws.py\", line 115, in symbol_to_hsmtoken\n    datadict[hsm_symbol] = symbol\n             ^^^^^^^^^^\nUnboundLocalError: cannot access local variable 'hsm_symbol' where it is not associated with a value","exception_name":"UnboundLocalError"}
{"level":"ERROR","location":"[__symbol_conversion:1374] data_ws","message":"'NoneType' object is not subscriptable","timestamp":"2024-09-09 12:53:49,442+0530","service":"FyersDataSocket","exception":"Traceback (most recent call last):\n  File \"C:\\Users\\USER\\AppData\\Local\\Programs\\Python\\Python312\\Lib\\site-packages\\fyers_apiv3\\FyersWebsocket\\data_ws.py\", line 1333, in __symbol_conversion\n    if symbol_value[3] != \"\":\n       ~~~~~~~~~~~~^^^\nTypeError: 'NoneType' object is not subscriptable","exception_name":"TypeError"}
{"level":"ERROR","location":"[<lambda>:1663] data_ws","message":"Connection to remote host was lost.","timestamp":"2024-09-09 13:25:47,016+0530","service":"FyersDataSocket"}
{"level":"ERROR","location":"[symbol_to_hsmtoken:126] data_ws","message":"cannot access local variable 'hsm_symbol' where it is not associated with a value","timestamp":"2024-09-09 13:25:58,497+0530","service":"FyersDataSocket","exception":"Traceback (most recent call last):\n  File \"C:\\Users\\USER\\AppData\\Local\\Programs\\Python\\Python312\\Lib\\site-packages\\websocket\\_app.py\", line 428, in setSock\n    dispatcher.read(self.sock.sock, read, check)\n  File \"C:\\Users\\USER\\AppData\\Local\\Programs\\Python\\Python312\\Lib\\site-packages\\websocket\\_app.py\", line 99, in read\n    if not read_callback():\n           ^^^^^^^^^^^^^^^\n  File \"C:\\Users\\USER\\AppData\\Local\\Programs\\Python\\Python312\\Lib\\site-packages\\websocket\\_app.py\", line 442, in read\n    raise e\n  File \"C:\\Users\\USER\\AppData\\Local\\Programs\\Python\\Python312\\Lib\\site-packages\\websocket\\_app.py\", line 437, in read\n    op_code, frame = self.sock.recv_data_frame(True)\n                     ^^^^^^^^^^^^^^^^^^^^^^^^^^^^^^^\n  File \"C:\\Users\\USER\\AppData\\Local\\Programs\\Python\\Python312\\Lib\\site-packages\\websocket\\_core.py\", line 406, in recv_data_frame\n    frame = self.recv_frame()\n            ^^^^^^^^^^^^^^^^^\n  File \"C:\\Users\\USER\\AppData\\Local\\Programs\\Python\\Python312\\Lib\\site-packages\\websocket\\_core.py\", line 445, in recv_frame\n    return self.frame_buffer.recv_frame()\n           ^^^^^^^^^^^^^^^^^^^^^^^^^^^^^^\n  File \"C:\\Users\\USER\\AppData\\Local\\Programs\\Python\\Python312\\Lib\\site-packages\\websocket\\_abnf.py\", line 338, in recv_frame\n    self.recv_header()\n  File \"C:\\Users\\USER\\AppData\\Local\\Programs\\Python\\Python312\\Lib\\site-packages\\websocket\\_abnf.py\", line 294, in recv_header\n    header = self.recv_strict(2)\n             ^^^^^^^^^^^^^^^^^^^\n  File \"C:\\Users\\USER\\AppData\\Local\\Programs\\Python\\Python312\\Lib\\site-packages\\websocket\\_abnf.py\", line 373, in recv_strict\n    bytes_ = self.recv(min(16384, shortage))\n             ^^^^^^^^^^^^^^^^^^^^^^^^^^^^^^^\n  File \"C:\\Users\\USER\\AppData\\Local\\Programs\\Python\\Python312\\Lib\\site-packages\\websocket\\_core.py\", line 529, in _recv\n    return recv(self.sock, bufsize)\n           ^^^^^^^^^^^^^^^^^^^^^^^^\n  File \"C:\\Users\\USER\\AppData\\Local\\Programs\\Python\\Python312\\Lib\\site-packages\\websocket\\_socket.py\", line 122, in recv\n    raise WebSocketConnectionClosedException(\nwebsocket._exceptions.WebSocketConnectionClosedException: Connection to remote host was lost.\n\nDuring handling of the above exception, another exception occurred:\n\nTraceback (most recent call last):\n  File \"C:\\Users\\USER\\AppData\\Local\\Programs\\Python\\Python312\\Lib\\site-packages\\fyers_apiv3\\FyersWebsocket\\data_ws.py\", line 115, in symbol_to_hsmtoken\n    datadict[hsm_symbol] = symbol\n             ^^^^^^^^^^\nUnboundLocalError: cannot access local variable 'hsm_symbol' where it is not associated with a value","exception_name":"UnboundLocalError"}
{"level":"ERROR","location":"[__symbol_conversion:1374] data_ws","message":"'NoneType' object is not subscriptable","timestamp":"2024-09-09 13:25:58,649+0530","service":"FyersDataSocket","exception":"Traceback (most recent call last):\n  File \"C:\\Users\\USER\\AppData\\Local\\Programs\\Python\\Python312\\Lib\\site-packages\\websocket\\_app.py\", line 428, in setSock\n    dispatcher.read(self.sock.sock, read, check)\n  File \"C:\\Users\\USER\\AppData\\Local\\Programs\\Python\\Python312\\Lib\\site-packages\\websocket\\_app.py\", line 99, in read\n    if not read_callback():\n           ^^^^^^^^^^^^^^^\n  File \"C:\\Users\\USER\\AppData\\Local\\Programs\\Python\\Python312\\Lib\\site-packages\\websocket\\_app.py\", line 442, in read\n    raise e\n  File \"C:\\Users\\USER\\AppData\\Local\\Programs\\Python\\Python312\\Lib\\site-packages\\websocket\\_app.py\", line 437, in read\n    op_code, frame = self.sock.recv_data_frame(True)\n                     ^^^^^^^^^^^^^^^^^^^^^^^^^^^^^^^\n  File \"C:\\Users\\USER\\AppData\\Local\\Programs\\Python\\Python312\\Lib\\site-packages\\websocket\\_core.py\", line 406, in recv_data_frame\n    frame = self.recv_frame()\n            ^^^^^^^^^^^^^^^^^\n  File \"C:\\Users\\USER\\AppData\\Local\\Programs\\Python\\Python312\\Lib\\site-packages\\websocket\\_core.py\", line 445, in recv_frame\n    return self.frame_buffer.recv_frame()\n           ^^^^^^^^^^^^^^^^^^^^^^^^^^^^^^\n  File \"C:\\Users\\USER\\AppData\\Local\\Programs\\Python\\Python312\\Lib\\site-packages\\websocket\\_abnf.py\", line 338, in recv_frame\n    self.recv_header()\n  File \"C:\\Users\\USER\\AppData\\Local\\Programs\\Python\\Python312\\Lib\\site-packages\\websocket\\_abnf.py\", line 294, in recv_header\n    header = self.recv_strict(2)\n             ^^^^^^^^^^^^^^^^^^^\n  File \"C:\\Users\\USER\\AppData\\Local\\Programs\\Python\\Python312\\Lib\\site-packages\\websocket\\_abnf.py\", line 373, in recv_strict\n    bytes_ = self.recv(min(16384, shortage))\n             ^^^^^^^^^^^^^^^^^^^^^^^^^^^^^^^\n  File \"C:\\Users\\USER\\AppData\\Local\\Programs\\Python\\Python312\\Lib\\site-packages\\websocket\\_core.py\", line 529, in _recv\n    return recv(self.sock, bufsize)\n           ^^^^^^^^^^^^^^^^^^^^^^^^\n  File \"C:\\Users\\USER\\AppData\\Local\\Programs\\Python\\Python312\\Lib\\site-packages\\websocket\\_socket.py\", line 122, in recv\n    raise WebSocketConnectionClosedException(\nwebsocket._exceptions.WebSocketConnectionClosedException: Connection to remote host was lost.\n\nDuring handling of the above exception, another exception occurred:\n\nTraceback (most recent call last):\n  File \"C:\\Users\\USER\\AppData\\Local\\Programs\\Python\\Python312\\Lib\\site-packages\\fyers_apiv3\\FyersWebsocket\\data_ws.py\", line 1333, in __symbol_conversion\n    if symbol_value[3] != \"\":\n       ~~~~~~~~~~~~^^^\nTypeError: 'NoneType' object is not subscriptable","exception_name":"TypeError"}
{"level":"ERROR","location":"[symbol_to_hsmtoken:126] data_ws","message":"cannot access local variable 'hsm_symbol' where it is not associated with a value","timestamp":"2024-09-09 16:01:15,204+0530","service":"FyersDataSocket","exception":"Traceback (most recent call last):\n  File \"C:\\Users\\USER\\AppData\\Local\\Programs\\Python\\Python312\\Lib\\site-packages\\fyers_apiv3\\FyersWebsocket\\data_ws.py\", line 115, in symbol_to_hsmtoken\n    datadict[hsm_symbol] = symbol\n             ^^^^^^^^^^\nUnboundLocalError: cannot access local variable 'hsm_symbol' where it is not associated with a value","exception_name":"UnboundLocalError"}
{"level":"ERROR","location":"[__symbol_conversion:1374] data_ws","message":"'NoneType' object is not subscriptable","timestamp":"2024-09-09 16:01:15,220+0530","service":"FyersDataSocket","exception":"Traceback (most recent call last):\n  File \"C:\\Users\\USER\\AppData\\Local\\Programs\\Python\\Python312\\Lib\\site-packages\\fyers_apiv3\\FyersWebsocket\\data_ws.py\", line 1333, in __symbol_conversion\n    if symbol_value[3] != \"\":\n       ~~~~~~~~~~~~^^^\nTypeError: 'NoneType' object is not subscriptable","exception_name":"TypeError"}
{"level":"ERROR","location":"[symbol_to_hsmtoken:126] data_ws","message":"cannot access local variable 'hsm_symbol' where it is not associated with a value","timestamp":"2024-09-09 16:04:42,703+0530","service":"FyersDataSocket","exception":"Traceback (most recent call last):\n  File \"C:\\Users\\USER\\AppData\\Local\\Programs\\Python\\Python312\\Lib\\site-packages\\fyers_apiv3\\FyersWebsocket\\data_ws.py\", line 115, in symbol_to_hsmtoken\n    datadict[hsm_symbol] = symbol\n             ^^^^^^^^^^\nUnboundLocalError: cannot access local variable 'hsm_symbol' where it is not associated with a value","exception_name":"UnboundLocalError"}
{"level":"ERROR","location":"[__symbol_conversion:1374] data_ws","message":"'NoneType' object is not subscriptable","timestamp":"2024-09-09 16:04:42,707+0530","service":"FyersDataSocket","exception":"Traceback (most recent call last):\n  File \"C:\\Users\\USER\\AppData\\Local\\Programs\\Python\\Python312\\Lib\\site-packages\\fyers_apiv3\\FyersWebsocket\\data_ws.py\", line 1333, in __symbol_conversion\n    if symbol_value[3] != \"\":\n       ~~~~~~~~~~~~^^^\nTypeError: 'NoneType' object is not subscriptable","exception_name":"TypeError"}
{"level":"ERROR","location":"[<lambda>:1663] data_ws","message":"Connection to remote host was lost.","timestamp":"2024-09-09 16:06:30,129+0530","service":"FyersDataSocket"}
{"level":"ERROR","location":"[symbol_to_hsmtoken:126] data_ws","message":"cannot access local variable 'hsm_symbol' where it is not associated with a value","timestamp":"2024-09-09 16:06:38,403+0530","service":"FyersDataSocket","exception":"Traceback (most recent call last):\n  File \"C:\\Users\\USER\\AppData\\Local\\Programs\\Python\\Python312\\Lib\\site-packages\\websocket\\_app.py\", line 428, in setSock\n    dispatcher.read(self.sock.sock, read, check)\n  File \"C:\\Users\\USER\\AppData\\Local\\Programs\\Python\\Python312\\Lib\\site-packages\\websocket\\_app.py\", line 99, in read\n    if not read_callback():\n           ^^^^^^^^^^^^^^^\n  File \"C:\\Users\\USER\\AppData\\Local\\Programs\\Python\\Python312\\Lib\\site-packages\\websocket\\_app.py\", line 442, in read\n    raise e\n  File \"C:\\Users\\USER\\AppData\\Local\\Programs\\Python\\Python312\\Lib\\site-packages\\websocket\\_app.py\", line 437, in read\n    op_code, frame = self.sock.recv_data_frame(True)\n                     ^^^^^^^^^^^^^^^^^^^^^^^^^^^^^^^\n  File \"C:\\Users\\USER\\AppData\\Local\\Programs\\Python\\Python312\\Lib\\site-packages\\websocket\\_core.py\", line 406, in recv_data_frame\n    frame = self.recv_frame()\n            ^^^^^^^^^^^^^^^^^\n  File \"C:\\Users\\USER\\AppData\\Local\\Programs\\Python\\Python312\\Lib\\site-packages\\websocket\\_core.py\", line 445, in recv_frame\n    return self.frame_buffer.recv_frame()\n           ^^^^^^^^^^^^^^^^^^^^^^^^^^^^^^\n  File \"C:\\Users\\USER\\AppData\\Local\\Programs\\Python\\Python312\\Lib\\site-packages\\websocket\\_abnf.py\", line 338, in recv_frame\n    self.recv_header()\n  File \"C:\\Users\\USER\\AppData\\Local\\Programs\\Python\\Python312\\Lib\\site-packages\\websocket\\_abnf.py\", line 294, in recv_header\n    header = self.recv_strict(2)\n             ^^^^^^^^^^^^^^^^^^^\n  File \"C:\\Users\\USER\\AppData\\Local\\Programs\\Python\\Python312\\Lib\\site-packages\\websocket\\_abnf.py\", line 373, in recv_strict\n    bytes_ = self.recv(min(16384, shortage))\n             ^^^^^^^^^^^^^^^^^^^^^^^^^^^^^^^\n  File \"C:\\Users\\USER\\AppData\\Local\\Programs\\Python\\Python312\\Lib\\site-packages\\websocket\\_core.py\", line 529, in _recv\n    return recv(self.sock, bufsize)\n           ^^^^^^^^^^^^^^^^^^^^^^^^\n  File \"C:\\Users\\USER\\AppData\\Local\\Programs\\Python\\Python312\\Lib\\site-packages\\websocket\\_socket.py\", line 122, in recv\n    raise WebSocketConnectionClosedException(\nwebsocket._exceptions.WebSocketConnectionClosedException: Connection to remote host was lost.\n\nDuring handling of the above exception, another exception occurred:\n\nTraceback (most recent call last):\n  File \"C:\\Users\\USER\\AppData\\Local\\Programs\\Python\\Python312\\Lib\\site-packages\\fyers_apiv3\\FyersWebsocket\\data_ws.py\", line 115, in symbol_to_hsmtoken\n    datadict[hsm_symbol] = symbol\n             ^^^^^^^^^^\nUnboundLocalError: cannot access local variable 'hsm_symbol' where it is not associated with a value","exception_name":"UnboundLocalError"}
{"level":"ERROR","location":"[__symbol_conversion:1374] data_ws","message":"'NoneType' object is not subscriptable","timestamp":"2024-09-09 16:06:38,427+0530","service":"FyersDataSocket","exception":"Traceback (most recent call last):\n  File \"C:\\Users\\USER\\AppData\\Local\\Programs\\Python\\Python312\\Lib\\site-packages\\websocket\\_app.py\", line 428, in setSock\n    dispatcher.read(self.sock.sock, read, check)\n  File \"C:\\Users\\USER\\AppData\\Local\\Programs\\Python\\Python312\\Lib\\site-packages\\websocket\\_app.py\", line 99, in read\n    if not read_callback():\n           ^^^^^^^^^^^^^^^\n  File \"C:\\Users\\USER\\AppData\\Local\\Programs\\Python\\Python312\\Lib\\site-packages\\websocket\\_app.py\", line 442, in read\n    raise e\n  File \"C:\\Users\\USER\\AppData\\Local\\Programs\\Python\\Python312\\Lib\\site-packages\\websocket\\_app.py\", line 437, in read\n    op_code, frame = self.sock.recv_data_frame(True)\n                     ^^^^^^^^^^^^^^^^^^^^^^^^^^^^^^^\n  File \"C:\\Users\\USER\\AppData\\Local\\Programs\\Python\\Python312\\Lib\\site-packages\\websocket\\_core.py\", line 406, in recv_data_frame\n    frame = self.recv_frame()\n            ^^^^^^^^^^^^^^^^^\n  File \"C:\\Users\\USER\\AppData\\Local\\Programs\\Python\\Python312\\Lib\\site-packages\\websocket\\_core.py\", line 445, in recv_frame\n    return self.frame_buffer.recv_frame()\n           ^^^^^^^^^^^^^^^^^^^^^^^^^^^^^^\n  File \"C:\\Users\\USER\\AppData\\Local\\Programs\\Python\\Python312\\Lib\\site-packages\\websocket\\_abnf.py\", line 338, in recv_frame\n    self.recv_header()\n  File \"C:\\Users\\USER\\AppData\\Local\\Programs\\Python\\Python312\\Lib\\site-packages\\websocket\\_abnf.py\", line 294, in recv_header\n    header = self.recv_strict(2)\n             ^^^^^^^^^^^^^^^^^^^\n  File \"C:\\Users\\USER\\AppData\\Local\\Programs\\Python\\Python312\\Lib\\site-packages\\websocket\\_abnf.py\", line 373, in recv_strict\n    bytes_ = self.recv(min(16384, shortage))\n             ^^^^^^^^^^^^^^^^^^^^^^^^^^^^^^^\n  File \"C:\\Users\\USER\\AppData\\Local\\Programs\\Python\\Python312\\Lib\\site-packages\\websocket\\_core.py\", line 529, in _recv\n    return recv(self.sock, bufsize)\n           ^^^^^^^^^^^^^^^^^^^^^^^^\n  File \"C:\\Users\\USER\\AppData\\Local\\Programs\\Python\\Python312\\Lib\\site-packages\\websocket\\_socket.py\", line 122, in recv\n    raise WebSocketConnectionClosedException(\nwebsocket._exceptions.WebSocketConnectionClosedException: Connection to remote host was lost.\n\nDuring handling of the above exception, another exception occurred:\n\nTraceback (most recent call last):\n  File \"C:\\Users\\USER\\AppData\\Local\\Programs\\Python\\Python312\\Lib\\site-packages\\fyers_apiv3\\FyersWebsocket\\data_ws.py\", line 1333, in __symbol_conversion\n    if symbol_value[3] != \"\":\n       ~~~~~~~~~~~~^^^\nTypeError: 'NoneType' object is not subscriptable","exception_name":"TypeError"}
{"level":"ERROR","location":"[__symbol_conversion:1352] data_ws","message":{"code":-300,"message":"Please provide a valid symbol","s":"error","type":"sub","invalid_symbols":["MCX:COTTONCNDY24DECFUT"]},"timestamp":"2024-09-09 16:09:14,637+0530","service":"FyersDataSocket"}
{"level":"ERROR","location":"[symbol_to_hsmtoken:126] data_ws","message":"cannot access local variable 'hsm_symbol' where it is not associated with a value","timestamp":"2024-09-09 16:10:25,587+0530","service":"FyersDataSocket","exception":"Traceback (most recent call last):\n  File \"C:\\Users\\USER\\AppData\\Local\\Programs\\Python\\Python312\\Lib\\site-packages\\fyers_apiv3\\FyersWebsocket\\data_ws.py\", line 115, in symbol_to_hsmtoken\n    datadict[hsm_symbol] = symbol\n             ^^^^^^^^^^\nUnboundLocalError: cannot access local variable 'hsm_symbol' where it is not associated with a value","exception_name":"UnboundLocalError"}
{"level":"ERROR","location":"[__symbol_conversion:1374] data_ws","message":"'NoneType' object is not subscriptable","timestamp":"2024-09-09 16:10:25,600+0530","service":"FyersDataSocket","exception":"Traceback (most recent call last):\n  File \"C:\\Users\\USER\\AppData\\Local\\Programs\\Python\\Python312\\Lib\\site-packages\\fyers_apiv3\\FyersWebsocket\\data_ws.py\", line 1333, in __symbol_conversion\n    if symbol_value[3] != \"\":\n       ~~~~~~~~~~~~^^^\nTypeError: 'NoneType' object is not subscriptable","exception_name":"TypeError"}
{"level":"ERROR","location":"[<lambda>:1663] data_ws","message":"Connection to remote host was lost.","timestamp":"2024-09-09 16:12:05,535+0530","service":"FyersDataSocket"}
{"level":"ERROR","location":"[symbol_to_hsmtoken:126] data_ws","message":"cannot access local variable 'hsm_symbol' where it is not associated with a value","timestamp":"2024-09-09 16:12:13,813+0530","service":"FyersDataSocket","exception":"Traceback (most recent call last):\n  File \"C:\\Users\\USER\\AppData\\Local\\Programs\\Python\\Python312\\Lib\\site-packages\\websocket\\_app.py\", line 428, in setSock\n    dispatcher.read(self.sock.sock, read, check)\n  File \"C:\\Users\\USER\\AppData\\Local\\Programs\\Python\\Python312\\Lib\\site-packages\\websocket\\_app.py\", line 99, in read\n    if not read_callback():\n           ^^^^^^^^^^^^^^^\n  File \"C:\\Users\\USER\\AppData\\Local\\Programs\\Python\\Python312\\Lib\\site-packages\\websocket\\_app.py\", line 442, in read\n    raise e\n  File \"C:\\Users\\USER\\AppData\\Local\\Programs\\Python\\Python312\\Lib\\site-packages\\websocket\\_app.py\", line 437, in read\n    op_code, frame = self.sock.recv_data_frame(True)\n                     ^^^^^^^^^^^^^^^^^^^^^^^^^^^^^^^\n  File \"C:\\Users\\USER\\AppData\\Local\\Programs\\Python\\Python312\\Lib\\site-packages\\websocket\\_core.py\", line 406, in recv_data_frame\n    frame = self.recv_frame()\n            ^^^^^^^^^^^^^^^^^\n  File \"C:\\Users\\USER\\AppData\\Local\\Programs\\Python\\Python312\\Lib\\site-packages\\websocket\\_core.py\", line 445, in recv_frame\n    return self.frame_buffer.recv_frame()\n           ^^^^^^^^^^^^^^^^^^^^^^^^^^^^^^\n  File \"C:\\Users\\USER\\AppData\\Local\\Programs\\Python\\Python312\\Lib\\site-packages\\websocket\\_abnf.py\", line 338, in recv_frame\n    self.recv_header()\n  File \"C:\\Users\\USER\\AppData\\Local\\Programs\\Python\\Python312\\Lib\\site-packages\\websocket\\_abnf.py\", line 294, in recv_header\n    header = self.recv_strict(2)\n             ^^^^^^^^^^^^^^^^^^^\n  File \"C:\\Users\\USER\\AppData\\Local\\Programs\\Python\\Python312\\Lib\\site-packages\\websocket\\_abnf.py\", line 373, in recv_strict\n    bytes_ = self.recv(min(16384, shortage))\n             ^^^^^^^^^^^^^^^^^^^^^^^^^^^^^^^\n  File \"C:\\Users\\USER\\AppData\\Local\\Programs\\Python\\Python312\\Lib\\site-packages\\websocket\\_core.py\", line 529, in _recv\n    return recv(self.sock, bufsize)\n           ^^^^^^^^^^^^^^^^^^^^^^^^\n  File \"C:\\Users\\USER\\AppData\\Local\\Programs\\Python\\Python312\\Lib\\site-packages\\websocket\\_socket.py\", line 122, in recv\n    raise WebSocketConnectionClosedException(\nwebsocket._exceptions.WebSocketConnectionClosedException: Connection to remote host was lost.\n\nDuring handling of the above exception, another exception occurred:\n\nTraceback (most recent call last):\n  File \"C:\\Users\\USER\\AppData\\Local\\Programs\\Python\\Python312\\Lib\\site-packages\\fyers_apiv3\\FyersWebsocket\\data_ws.py\", line 115, in symbol_to_hsmtoken\n    datadict[hsm_symbol] = symbol\n             ^^^^^^^^^^\nUnboundLocalError: cannot access local variable 'hsm_symbol' where it is not associated with a value","exception_name":"UnboundLocalError"}
{"level":"ERROR","location":"[__symbol_conversion:1374] data_ws","message":"'NoneType' object is not subscriptable","timestamp":"2024-09-09 16:12:13,821+0530","service":"FyersDataSocket","exception":"Traceback (most recent call last):\n  File \"C:\\Users\\USER\\AppData\\Local\\Programs\\Python\\Python312\\Lib\\site-packages\\websocket\\_app.py\", line 428, in setSock\n    dispatcher.read(self.sock.sock, read, check)\n  File \"C:\\Users\\USER\\AppData\\Local\\Programs\\Python\\Python312\\Lib\\site-packages\\websocket\\_app.py\", line 99, in read\n    if not read_callback():\n           ^^^^^^^^^^^^^^^\n  File \"C:\\Users\\USER\\AppData\\Local\\Programs\\Python\\Python312\\Lib\\site-packages\\websocket\\_app.py\", line 442, in read\n    raise e\n  File \"C:\\Users\\USER\\AppData\\Local\\Programs\\Python\\Python312\\Lib\\site-packages\\websocket\\_app.py\", line 437, in read\n    op_code, frame = self.sock.recv_data_frame(True)\n                     ^^^^^^^^^^^^^^^^^^^^^^^^^^^^^^^\n  File \"C:\\Users\\USER\\AppData\\Local\\Programs\\Python\\Python312\\Lib\\site-packages\\websocket\\_core.py\", line 406, in recv_data_frame\n    frame = self.recv_frame()\n            ^^^^^^^^^^^^^^^^^\n  File \"C:\\Users\\USER\\AppData\\Local\\Programs\\Python\\Python312\\Lib\\site-packages\\websocket\\_core.py\", line 445, in recv_frame\n    return self.frame_buffer.recv_frame()\n           ^^^^^^^^^^^^^^^^^^^^^^^^^^^^^^\n  File \"C:\\Users\\USER\\AppData\\Local\\Programs\\Python\\Python312\\Lib\\site-packages\\websocket\\_abnf.py\", line 338, in recv_frame\n    self.recv_header()\n  File \"C:\\Users\\USER\\AppData\\Local\\Programs\\Python\\Python312\\Lib\\site-packages\\websocket\\_abnf.py\", line 294, in recv_header\n    header = self.recv_strict(2)\n             ^^^^^^^^^^^^^^^^^^^\n  File \"C:\\Users\\USER\\AppData\\Local\\Programs\\Python\\Python312\\Lib\\site-packages\\websocket\\_abnf.py\", line 373, in recv_strict\n    bytes_ = self.recv(min(16384, shortage))\n             ^^^^^^^^^^^^^^^^^^^^^^^^^^^^^^^\n  File \"C:\\Users\\USER\\AppData\\Local\\Programs\\Python\\Python312\\Lib\\site-packages\\websocket\\_core.py\", line 529, in _recv\n    return recv(self.sock, bufsize)\n           ^^^^^^^^^^^^^^^^^^^^^^^^\n  File \"C:\\Users\\USER\\AppData\\Local\\Programs\\Python\\Python312\\Lib\\site-packages\\websocket\\_socket.py\", line 122, in recv\n    raise WebSocketConnectionClosedException(\nwebsocket._exceptions.WebSocketConnectionClosedException: Connection to remote host was lost.\n\nDuring handling of the above exception, another exception occurred:\n\nTraceback (most recent call last):\n  File \"C:\\Users\\USER\\AppData\\Local\\Programs\\Python\\Python312\\Lib\\site-packages\\fyers_apiv3\\FyersWebsocket\\data_ws.py\", line 1333, in __symbol_conversion\n    if symbol_value[3] != \"\":\n       ~~~~~~~~~~~~^^^\nTypeError: 'NoneType' object is not subscriptable","exception_name":"TypeError"}
{"level":"ERROR","location":"[symbol_to_hsmtoken:126] data_ws","message":"cannot access local variable 'hsm_symbol' where it is not associated with a value","timestamp":"2024-09-09 16:14:05,917+0530","service":"FyersDataSocket","exception":"Traceback (most recent call last):\n  File \"C:\\Users\\USER\\AppData\\Local\\Programs\\Python\\Python312\\Lib\\site-packages\\fyers_apiv3\\FyersWebsocket\\data_ws.py\", line 115, in symbol_to_hsmtoken\n    datadict[hsm_symbol] = symbol\n             ^^^^^^^^^^\nUnboundLocalError: cannot access local variable 'hsm_symbol' where it is not associated with a value","exception_name":"UnboundLocalError"}
{"level":"ERROR","location":"[__symbol_conversion:1374] data_ws","message":"'NoneType' object is not subscriptable","timestamp":"2024-09-09 16:14:05,927+0530","service":"FyersDataSocket","exception":"Traceback (most recent call last):\n  File \"C:\\Users\\USER\\AppData\\Local\\Programs\\Python\\Python312\\Lib\\site-packages\\fyers_apiv3\\FyersWebsocket\\data_ws.py\", line 1333, in __symbol_conversion\n    if symbol_value[3] != \"\":\n       ~~~~~~~~~~~~^^^\nTypeError: 'NoneType' object is not subscriptable","exception_name":"TypeError"}
{"level":"ERROR","location":"[<lambda>:1663] data_ws","message":"Connection to remote host was lost.","timestamp":"2024-09-09 16:15:53,375+0530","service":"FyersDataSocket"}
{"level":"ERROR","location":"[symbol_to_hsmtoken:126] data_ws","message":"cannot access local variable 'hsm_symbol' where it is not associated with a value","timestamp":"2024-09-09 16:16:01,465+0530","service":"FyersDataSocket","exception":"Traceback (most recent call last):\n  File \"C:\\Users\\USER\\AppData\\Local\\Programs\\Python\\Python312\\Lib\\site-packages\\websocket\\_app.py\", line 428, in setSock\n    dispatcher.read(self.sock.sock, read, check)\n  File \"C:\\Users\\USER\\AppData\\Local\\Programs\\Python\\Python312\\Lib\\site-packages\\websocket\\_app.py\", line 99, in read\n    if not read_callback():\n           ^^^^^^^^^^^^^^^\n  File \"C:\\Users\\USER\\AppData\\Local\\Programs\\Python\\Python312\\Lib\\site-packages\\websocket\\_app.py\", line 442, in read\n    raise e\n  File \"C:\\Users\\USER\\AppData\\Local\\Programs\\Python\\Python312\\Lib\\site-packages\\websocket\\_app.py\", line 437, in read\n    op_code, frame = self.sock.recv_data_frame(True)\n                     ^^^^^^^^^^^^^^^^^^^^^^^^^^^^^^^\n  File \"C:\\Users\\USER\\AppData\\Local\\Programs\\Python\\Python312\\Lib\\site-packages\\websocket\\_core.py\", line 406, in recv_data_frame\n    frame = self.recv_frame()\n            ^^^^^^^^^^^^^^^^^\n  File \"C:\\Users\\USER\\AppData\\Local\\Programs\\Python\\Python312\\Lib\\site-packages\\websocket\\_core.py\", line 445, in recv_frame\n    return self.frame_buffer.recv_frame()\n           ^^^^^^^^^^^^^^^^^^^^^^^^^^^^^^\n  File \"C:\\Users\\USER\\AppData\\Local\\Programs\\Python\\Python312\\Lib\\site-packages\\websocket\\_abnf.py\", line 338, in recv_frame\n    self.recv_header()\n  File \"C:\\Users\\USER\\AppData\\Local\\Programs\\Python\\Python312\\Lib\\site-packages\\websocket\\_abnf.py\", line 294, in recv_header\n    header = self.recv_strict(2)\n             ^^^^^^^^^^^^^^^^^^^\n  File \"C:\\Users\\USER\\AppData\\Local\\Programs\\Python\\Python312\\Lib\\site-packages\\websocket\\_abnf.py\", line 373, in recv_strict\n    bytes_ = self.recv(min(16384, shortage))\n             ^^^^^^^^^^^^^^^^^^^^^^^^^^^^^^^\n  File \"C:\\Users\\USER\\AppData\\Local\\Programs\\Python\\Python312\\Lib\\site-packages\\websocket\\_core.py\", line 529, in _recv\n    return recv(self.sock, bufsize)\n           ^^^^^^^^^^^^^^^^^^^^^^^^\n  File \"C:\\Users\\USER\\AppData\\Local\\Programs\\Python\\Python312\\Lib\\site-packages\\websocket\\_socket.py\", line 122, in recv\n    raise WebSocketConnectionClosedException(\nwebsocket._exceptions.WebSocketConnectionClosedException: Connection to remote host was lost.\n\nDuring handling of the above exception, another exception occurred:\n\nTraceback (most recent call last):\n  File \"C:\\Users\\USER\\AppData\\Local\\Programs\\Python\\Python312\\Lib\\site-packages\\fyers_apiv3\\FyersWebsocket\\data_ws.py\", line 115, in symbol_to_hsmtoken\n    datadict[hsm_symbol] = symbol\n             ^^^^^^^^^^\nUnboundLocalError: cannot access local variable 'hsm_symbol' where it is not associated with a value","exception_name":"UnboundLocalError"}
{"level":"ERROR","location":"[__symbol_conversion:1374] data_ws","message":"'NoneType' object is not subscriptable","timestamp":"2024-09-09 16:16:01,477+0530","service":"FyersDataSocket","exception":"Traceback (most recent call last):\n  File \"C:\\Users\\USER\\AppData\\Local\\Programs\\Python\\Python312\\Lib\\site-packages\\websocket\\_app.py\", line 428, in setSock\n    dispatcher.read(self.sock.sock, read, check)\n  File \"C:\\Users\\USER\\AppData\\Local\\Programs\\Python\\Python312\\Lib\\site-packages\\websocket\\_app.py\", line 99, in read\n    if not read_callback():\n           ^^^^^^^^^^^^^^^\n  File \"C:\\Users\\USER\\AppData\\Local\\Programs\\Python\\Python312\\Lib\\site-packages\\websocket\\_app.py\", line 442, in read\n    raise e\n  File \"C:\\Users\\USER\\AppData\\Local\\Programs\\Python\\Python312\\Lib\\site-packages\\websocket\\_app.py\", line 437, in read\n    op_code, frame = self.sock.recv_data_frame(True)\n                     ^^^^^^^^^^^^^^^^^^^^^^^^^^^^^^^\n  File \"C:\\Users\\USER\\AppData\\Local\\Programs\\Python\\Python312\\Lib\\site-packages\\websocket\\_core.py\", line 406, in recv_data_frame\n    frame = self.recv_frame()\n            ^^^^^^^^^^^^^^^^^\n  File \"C:\\Users\\USER\\AppData\\Local\\Programs\\Python\\Python312\\Lib\\site-packages\\websocket\\_core.py\", line 445, in recv_frame\n    return self.frame_buffer.recv_frame()\n           ^^^^^^^^^^^^^^^^^^^^^^^^^^^^^^\n  File \"C:\\Users\\USER\\AppData\\Local\\Programs\\Python\\Python312\\Lib\\site-packages\\websocket\\_abnf.py\", line 338, in recv_frame\n    self.recv_header()\n  File \"C:\\Users\\USER\\AppData\\Local\\Programs\\Python\\Python312\\Lib\\site-packages\\websocket\\_abnf.py\", line 294, in recv_header\n    header = self.recv_strict(2)\n             ^^^^^^^^^^^^^^^^^^^\n  File \"C:\\Users\\USER\\AppData\\Local\\Programs\\Python\\Python312\\Lib\\site-packages\\websocket\\_abnf.py\", line 373, in recv_strict\n    bytes_ = self.recv(min(16384, shortage))\n             ^^^^^^^^^^^^^^^^^^^^^^^^^^^^^^^\n  File \"C:\\Users\\USER\\AppData\\Local\\Programs\\Python\\Python312\\Lib\\site-packages\\websocket\\_core.py\", line 529, in _recv\n    return recv(self.sock, bufsize)\n           ^^^^^^^^^^^^^^^^^^^^^^^^\n  File \"C:\\Users\\USER\\AppData\\Local\\Programs\\Python\\Python312\\Lib\\site-packages\\websocket\\_socket.py\", line 122, in recv\n    raise WebSocketConnectionClosedException(\nwebsocket._exceptions.WebSocketConnectionClosedException: Connection to remote host was lost.\n\nDuring handling of the above exception, another exception occurred:\n\nTraceback (most recent call last):\n  File \"C:\\Users\\USER\\AppData\\Local\\Programs\\Python\\Python312\\Lib\\site-packages\\fyers_apiv3\\FyersWebsocket\\data_ws.py\", line 1333, in __symbol_conversion\n    if symbol_value[3] != \"\":\n       ~~~~~~~~~~~~^^^\nTypeError: 'NoneType' object is not subscriptable","exception_name":"TypeError"}
{"level":"ERROR","location":"[<lambda>:1663] data_ws","message":"Connection to remote host was lost.","timestamp":"2024-09-09 16:35:23,637+0530","service":"FyersDataSocket"}
{"level":"ERROR","location":"[symbol_to_hsmtoken:126] data_ws","message":"cannot access local variable 'hsm_symbol' where it is not associated with a value","timestamp":"2024-09-09 16:35:35,711+0530","service":"FyersDataSocket","exception":"Traceback (most recent call last):\n  File \"C:\\Users\\USER\\AppData\\Local\\Programs\\Python\\Python312\\Lib\\site-packages\\websocket\\_app.py\", line 428, in setSock\n    dispatcher.read(self.sock.sock, read, check)\n  File \"C:\\Users\\USER\\AppData\\Local\\Programs\\Python\\Python312\\Lib\\site-packages\\websocket\\_app.py\", line 99, in read\n    if not read_callback():\n           ^^^^^^^^^^^^^^^\n  File \"C:\\Users\\USER\\AppData\\Local\\Programs\\Python\\Python312\\Lib\\site-packages\\websocket\\_app.py\", line 442, in read\n    raise e\n  File \"C:\\Users\\USER\\AppData\\Local\\Programs\\Python\\Python312\\Lib\\site-packages\\websocket\\_app.py\", line 437, in read\n    op_code, frame = self.sock.recv_data_frame(True)\n                     ^^^^^^^^^^^^^^^^^^^^^^^^^^^^^^^\n  File \"C:\\Users\\USER\\AppData\\Local\\Programs\\Python\\Python312\\Lib\\site-packages\\websocket\\_core.py\", line 406, in recv_data_frame\n    frame = self.recv_frame()\n            ^^^^^^^^^^^^^^^^^\n  File \"C:\\Users\\USER\\AppData\\Local\\Programs\\Python\\Python312\\Lib\\site-packages\\websocket\\_core.py\", line 445, in recv_frame\n    return self.frame_buffer.recv_frame()\n           ^^^^^^^^^^^^^^^^^^^^^^^^^^^^^^\n  File \"C:\\Users\\USER\\AppData\\Local\\Programs\\Python\\Python312\\Lib\\site-packages\\websocket\\_abnf.py\", line 338, in recv_frame\n    self.recv_header()\n  File \"C:\\Users\\USER\\AppData\\Local\\Programs\\Python\\Python312\\Lib\\site-packages\\websocket\\_abnf.py\", line 294, in recv_header\n    header = self.recv_strict(2)\n             ^^^^^^^^^^^^^^^^^^^\n  File \"C:\\Users\\USER\\AppData\\Local\\Programs\\Python\\Python312\\Lib\\site-packages\\websocket\\_abnf.py\", line 373, in recv_strict\n    bytes_ = self.recv(min(16384, shortage))\n             ^^^^^^^^^^^^^^^^^^^^^^^^^^^^^^^\n  File \"C:\\Users\\USER\\AppData\\Local\\Programs\\Python\\Python312\\Lib\\site-packages\\websocket\\_core.py\", line 529, in _recv\n    return recv(self.sock, bufsize)\n           ^^^^^^^^^^^^^^^^^^^^^^^^\n  File \"C:\\Users\\USER\\AppData\\Local\\Programs\\Python\\Python312\\Lib\\site-packages\\websocket\\_socket.py\", line 122, in recv\n    raise WebSocketConnectionClosedException(\nwebsocket._exceptions.WebSocketConnectionClosedException: Connection to remote host was lost.\n\nDuring handling of the above exception, another exception occurred:\n\nTraceback (most recent call last):\n  File \"C:\\Users\\USER\\AppData\\Local\\Programs\\Python\\Python312\\Lib\\site-packages\\fyers_apiv3\\FyersWebsocket\\data_ws.py\", line 115, in symbol_to_hsmtoken\n    datadict[hsm_symbol] = symbol\n             ^^^^^^^^^^\nUnboundLocalError: cannot access local variable 'hsm_symbol' where it is not associated with a value","exception_name":"UnboundLocalError"}
{"level":"ERROR","location":"[__symbol_conversion:1374] data_ws","message":"'NoneType' object is not subscriptable","timestamp":"2024-09-09 16:35:35,741+0530","service":"FyersDataSocket","exception":"Traceback (most recent call last):\n  File \"C:\\Users\\USER\\AppData\\Local\\Programs\\Python\\Python312\\Lib\\site-packages\\websocket\\_app.py\", line 428, in setSock\n    dispatcher.read(self.sock.sock, read, check)\n  File \"C:\\Users\\USER\\AppData\\Local\\Programs\\Python\\Python312\\Lib\\site-packages\\websocket\\_app.py\", line 99, in read\n    if not read_callback():\n           ^^^^^^^^^^^^^^^\n  File \"C:\\Users\\USER\\AppData\\Local\\Programs\\Python\\Python312\\Lib\\site-packages\\websocket\\_app.py\", line 442, in read\n    raise e\n  File \"C:\\Users\\USER\\AppData\\Local\\Programs\\Python\\Python312\\Lib\\site-packages\\websocket\\_app.py\", line 437, in read\n    op_code, frame = self.sock.recv_data_frame(True)\n                     ^^^^^^^^^^^^^^^^^^^^^^^^^^^^^^^\n  File \"C:\\Users\\USER\\AppData\\Local\\Programs\\Python\\Python312\\Lib\\site-packages\\websocket\\_core.py\", line 406, in recv_data_frame\n    frame = self.recv_frame()\n            ^^^^^^^^^^^^^^^^^\n  File \"C:\\Users\\USER\\AppData\\Local\\Programs\\Python\\Python312\\Lib\\site-packages\\websocket\\_core.py\", line 445, in recv_frame\n    return self.frame_buffer.recv_frame()\n           ^^^^^^^^^^^^^^^^^^^^^^^^^^^^^^\n  File \"C:\\Users\\USER\\AppData\\Local\\Programs\\Python\\Python312\\Lib\\site-packages\\websocket\\_abnf.py\", line 338, in recv_frame\n    self.recv_header()\n  File \"C:\\Users\\USER\\AppData\\Local\\Programs\\Python\\Python312\\Lib\\site-packages\\websocket\\_abnf.py\", line 294, in recv_header\n    header = self.recv_strict(2)\n             ^^^^^^^^^^^^^^^^^^^\n  File \"C:\\Users\\USER\\AppData\\Local\\Programs\\Python\\Python312\\Lib\\site-packages\\websocket\\_abnf.py\", line 373, in recv_strict\n    bytes_ = self.recv(min(16384, shortage))\n             ^^^^^^^^^^^^^^^^^^^^^^^^^^^^^^^\n  File \"C:\\Users\\USER\\AppData\\Local\\Programs\\Python\\Python312\\Lib\\site-packages\\websocket\\_core.py\", line 529, in _recv\n    return recv(self.sock, bufsize)\n           ^^^^^^^^^^^^^^^^^^^^^^^^\n  File \"C:\\Users\\USER\\AppData\\Local\\Programs\\Python\\Python312\\Lib\\site-packages\\websocket\\_socket.py\", line 122, in recv\n    raise WebSocketConnectionClosedException(\nwebsocket._exceptions.WebSocketConnectionClosedException: Connection to remote host was lost.\n\nDuring handling of the above exception, another exception occurred:\n\nTraceback (most recent call last):\n  File \"C:\\Users\\USER\\AppData\\Local\\Programs\\Python\\Python312\\Lib\\site-packages\\fyers_apiv3\\FyersWebsocket\\data_ws.py\", line 1333, in __symbol_conversion\n    if symbol_value[3] != \"\":\n       ~~~~~~~~~~~~^^^\nTypeError: 'NoneType' object is not subscriptable","exception_name":"TypeError"}
{"level":"ERROR","location":"[symbol_to_hsmtoken:126] data_ws","message":"cannot access local variable 'hsm_symbol' where it is not associated with a value","timestamp":"2024-09-09 16:37:02,681+0530","service":"FyersDataSocket","exception":"Traceback (most recent call last):\n  File \"C:\\Users\\USER\\AppData\\Local\\Programs\\Python\\Python312\\Lib\\site-packages\\fyers_apiv3\\FyersWebsocket\\data_ws.py\", line 115, in symbol_to_hsmtoken\n    datadict[hsm_symbol] = symbol\n             ^^^^^^^^^^\nUnboundLocalError: cannot access local variable 'hsm_symbol' where it is not associated with a value","exception_name":"UnboundLocalError"}
{"level":"ERROR","location":"[__symbol_conversion:1374] data_ws","message":"'NoneType' object is not subscriptable","timestamp":"2024-09-09 16:37:02,688+0530","service":"FyersDataSocket","exception":"Traceback (most recent call last):\n  File \"C:\\Users\\USER\\AppData\\Local\\Programs\\Python\\Python312\\Lib\\site-packages\\fyers_apiv3\\FyersWebsocket\\data_ws.py\", line 1333, in __symbol_conversion\n    if symbol_value[3] != \"\":\n       ~~~~~~~~~~~~^^^\nTypeError: 'NoneType' object is not subscriptable","exception_name":"TypeError"}
{"level":"ERROR","location":"[symbol_to_hsmtoken:126] data_ws","message":"cannot access local variable 'hsm_symbol' where it is not associated with a value","timestamp":"2024-09-09 16:50:56,200+0530","service":"FyersDataSocket","exception":"Traceback (most recent call last):\n  File \"C:\\Users\\USER\\AppData\\Local\\Programs\\Python\\Python312\\Lib\\site-packages\\fyers_apiv3\\FyersWebsocket\\data_ws.py\", line 115, in symbol_to_hsmtoken\n    datadict[hsm_symbol] = symbol\n             ^^^^^^^^^^\nUnboundLocalError: cannot access local variable 'hsm_symbol' where it is not associated with a value","exception_name":"UnboundLocalError"}
{"level":"ERROR","location":"[__symbol_conversion:1374] data_ws","message":"'NoneType' object is not subscriptable","timestamp":"2024-09-09 16:50:56,209+0530","service":"FyersDataSocket","exception":"Traceback (most recent call last):\n  File \"C:\\Users\\USER\\AppData\\Local\\Programs\\Python\\Python312\\Lib\\site-packages\\fyers_apiv3\\FyersWebsocket\\data_ws.py\", line 1333, in __symbol_conversion\n    if symbol_value[3] != \"\":\n       ~~~~~~~~~~~~^^^\nTypeError: 'NoneType' object is not subscriptable","exception_name":"TypeError"}
{"level":"ERROR","location":"[<lambda>:1663] data_ws","message":"Connection to remote host was lost.","timestamp":"2024-09-09 17:10:23,571+0530","service":"FyersDataSocket"}
{"level":"ERROR","location":"[symbol_to_hsmtoken:126] data_ws","message":"cannot access local variable 'hsm_symbol' where it is not associated with a value","timestamp":"2024-09-09 17:10:32,528+0530","service":"FyersDataSocket","exception":"Traceback (most recent call last):\n  File \"C:\\Users\\USER\\AppData\\Local\\Programs\\Python\\Python312\\Lib\\site-packages\\websocket\\_app.py\", line 428, in setSock\n    dispatcher.read(self.sock.sock, read, check)\n  File \"C:\\Users\\USER\\AppData\\Local\\Programs\\Python\\Python312\\Lib\\site-packages\\websocket\\_app.py\", line 99, in read\n    if not read_callback():\n           ^^^^^^^^^^^^^^^\n  File \"C:\\Users\\USER\\AppData\\Local\\Programs\\Python\\Python312\\Lib\\site-packages\\websocket\\_app.py\", line 442, in read\n    raise e\n  File \"C:\\Users\\USER\\AppData\\Local\\Programs\\Python\\Python312\\Lib\\site-packages\\websocket\\_app.py\", line 437, in read\n    op_code, frame = self.sock.recv_data_frame(True)\n                     ^^^^^^^^^^^^^^^^^^^^^^^^^^^^^^^\n  File \"C:\\Users\\USER\\AppData\\Local\\Programs\\Python\\Python312\\Lib\\site-packages\\websocket\\_core.py\", line 406, in recv_data_frame\n    frame = self.recv_frame()\n            ^^^^^^^^^^^^^^^^^\n  File \"C:\\Users\\USER\\AppData\\Local\\Programs\\Python\\Python312\\Lib\\site-packages\\websocket\\_core.py\", line 445, in recv_frame\n    return self.frame_buffer.recv_frame()\n           ^^^^^^^^^^^^^^^^^^^^^^^^^^^^^^\n  File \"C:\\Users\\USER\\AppData\\Local\\Programs\\Python\\Python312\\Lib\\site-packages\\websocket\\_abnf.py\", line 338, in recv_frame\n    self.recv_header()\n  File \"C:\\Users\\USER\\AppData\\Local\\Programs\\Python\\Python312\\Lib\\site-packages\\websocket\\_abnf.py\", line 294, in recv_header\n    header = self.recv_strict(2)\n             ^^^^^^^^^^^^^^^^^^^\n  File \"C:\\Users\\USER\\AppData\\Local\\Programs\\Python\\Python312\\Lib\\site-packages\\websocket\\_abnf.py\", line 373, in recv_strict\n    bytes_ = self.recv(min(16384, shortage))\n             ^^^^^^^^^^^^^^^^^^^^^^^^^^^^^^^\n  File \"C:\\Users\\USER\\AppData\\Local\\Programs\\Python\\Python312\\Lib\\site-packages\\websocket\\_core.py\", line 529, in _recv\n    return recv(self.sock, bufsize)\n           ^^^^^^^^^^^^^^^^^^^^^^^^\n  File \"C:\\Users\\USER\\AppData\\Local\\Programs\\Python\\Python312\\Lib\\site-packages\\websocket\\_socket.py\", line 122, in recv\n    raise WebSocketConnectionClosedException(\nwebsocket._exceptions.WebSocketConnectionClosedException: Connection to remote host was lost.\n\nDuring handling of the above exception, another exception occurred:\n\nTraceback (most recent call last):\n  File \"C:\\Users\\USER\\AppData\\Local\\Programs\\Python\\Python312\\Lib\\site-packages\\fyers_apiv3\\FyersWebsocket\\data_ws.py\", line 115, in symbol_to_hsmtoken\n    datadict[hsm_symbol] = symbol\n             ^^^^^^^^^^\nUnboundLocalError: cannot access local variable 'hsm_symbol' where it is not associated with a value","exception_name":"UnboundLocalError"}
{"level":"ERROR","location":"[__symbol_conversion:1374] data_ws","message":"'NoneType' object is not subscriptable","timestamp":"2024-09-09 17:10:32,565+0530","service":"FyersDataSocket","exception":"Traceback (most recent call last):\n  File \"C:\\Users\\USER\\AppData\\Local\\Programs\\Python\\Python312\\Lib\\site-packages\\websocket\\_app.py\", line 428, in setSock\n    dispatcher.read(self.sock.sock, read, check)\n  File \"C:\\Users\\USER\\AppData\\Local\\Programs\\Python\\Python312\\Lib\\site-packages\\websocket\\_app.py\", line 99, in read\n    if not read_callback():\n           ^^^^^^^^^^^^^^^\n  File \"C:\\Users\\USER\\AppData\\Local\\Programs\\Python\\Python312\\Lib\\site-packages\\websocket\\_app.py\", line 442, in read\n    raise e\n  File \"C:\\Users\\USER\\AppData\\Local\\Programs\\Python\\Python312\\Lib\\site-packages\\websocket\\_app.py\", line 437, in read\n    op_code, frame = self.sock.recv_data_frame(True)\n                     ^^^^^^^^^^^^^^^^^^^^^^^^^^^^^^^\n  File \"C:\\Users\\USER\\AppData\\Local\\Programs\\Python\\Python312\\Lib\\site-packages\\websocket\\_core.py\", line 406, in recv_data_frame\n    frame = self.recv_frame()\n            ^^^^^^^^^^^^^^^^^\n  File \"C:\\Users\\USER\\AppData\\Local\\Programs\\Python\\Python312\\Lib\\site-packages\\websocket\\_core.py\", line 445, in recv_frame\n    return self.frame_buffer.recv_frame()\n           ^^^^^^^^^^^^^^^^^^^^^^^^^^^^^^\n  File \"C:\\Users\\USER\\AppData\\Local\\Programs\\Python\\Python312\\Lib\\site-packages\\websocket\\_abnf.py\", line 338, in recv_frame\n    self.recv_header()\n  File \"C:\\Users\\USER\\AppData\\Local\\Programs\\Python\\Python312\\Lib\\site-packages\\websocket\\_abnf.py\", line 294, in recv_header\n    header = self.recv_strict(2)\n             ^^^^^^^^^^^^^^^^^^^\n  File \"C:\\Users\\USER\\AppData\\Local\\Programs\\Python\\Python312\\Lib\\site-packages\\websocket\\_abnf.py\", line 373, in recv_strict\n    bytes_ = self.recv(min(16384, shortage))\n             ^^^^^^^^^^^^^^^^^^^^^^^^^^^^^^^\n  File \"C:\\Users\\USER\\AppData\\Local\\Programs\\Python\\Python312\\Lib\\site-packages\\websocket\\_core.py\", line 529, in _recv\n    return recv(self.sock, bufsize)\n           ^^^^^^^^^^^^^^^^^^^^^^^^\n  File \"C:\\Users\\USER\\AppData\\Local\\Programs\\Python\\Python312\\Lib\\site-packages\\websocket\\_socket.py\", line 122, in recv\n    raise WebSocketConnectionClosedException(\nwebsocket._exceptions.WebSocketConnectionClosedException: Connection to remote host was lost.\n\nDuring handling of the above exception, another exception occurred:\n\nTraceback (most recent call last):\n  File \"C:\\Users\\USER\\AppData\\Local\\Programs\\Python\\Python312\\Lib\\site-packages\\fyers_apiv3\\FyersWebsocket\\data_ws.py\", line 1333, in __symbol_conversion\n    if symbol_value[3] != \"\":\n       ~~~~~~~~~~~~^^^\nTypeError: 'NoneType' object is not subscriptable","exception_name":"TypeError"}
{"level":"ERROR","location":"[On_message:1446] data_ws","message":"'NoneType' object cannot be interpreted as an integer","timestamp":"2024-09-09 17:33:43,020+0530","service":"FyersDataSocket","exception":"Traceback (most recent call last):\n  File \"C:\\Users\\USER\\AppData\\Local\\Programs\\Python\\Python312\\Lib\\site-packages\\fyers_apiv3\\FyersWebsocket\\data_ws.py\", line 1433, in On_message\n    self.OnMessage(message)\n  File \"c:\\Users\\USER\\AppData\\Local\\Temp\\ccd85ab7-a10f-476e-805e-c73c32ab36f2_python_scripts.zip.6f2\\python_scripts\\fyerapi.py\", line 198, in onmessage\n    timestamp = datetime.fromtimestamp(message.get(\"exch_feed_time\"))\n                ^^^^^^^^^^^^^^^^^^^^^^^^^^^^^^^^^^^^^^^^^^^^^^^^^^^^^\nTypeError: 'NoneType' object cannot be interpreted as an integer","exception_name":"TypeError"}
{"level":"ERROR","location":"[On_message:1447] data_ws","message":"'NoneType' object cannot be interpreted as an integer","timestamp":"2024-09-09 17:33:43,026+0530","service":"FyersDataSocket"}
{"level":"ERROR","location":"[symbol_to_hsmtoken:126] data_ws","message":"cannot access local variable 'hsm_symbol' where it is not associated with a value","timestamp":"2024-09-09 17:33:44,588+0530","service":"FyersDataSocket","exception":"Traceback (most recent call last):\n  File \"C:\\Users\\USER\\AppData\\Local\\Programs\\Python\\Python312\\Lib\\site-packages\\fyers_apiv3\\FyersWebsocket\\data_ws.py\", line 115, in symbol_to_hsmtoken\n    datadict[hsm_symbol] = symbol\n             ^^^^^^^^^^\nUnboundLocalError: cannot access local variable 'hsm_symbol' where it is not associated with a value","exception_name":"UnboundLocalError"}
{"level":"ERROR","location":"[__symbol_conversion:1374] data_ws","message":"'NoneType' object is not subscriptable","timestamp":"2024-09-09 17:33:44,592+0530","service":"FyersDataSocket","exception":"Traceback (most recent call last):\n  File \"C:\\Users\\USER\\AppData\\Local\\Programs\\Python\\Python312\\Lib\\site-packages\\fyers_apiv3\\FyersWebsocket\\data_ws.py\", line 1333, in __symbol_conversion\n    if symbol_value[3] != \"\":\n       ~~~~~~~~~~~~^^^\nTypeError: 'NoneType' object is not subscriptable","exception_name":"TypeError"}
{"level":"ERROR","location":"[On_message:1446] data_ws","message":"'NoneType' object cannot be interpreted as an integer","timestamp":"2024-09-09 17:35:30,809+0530","service":"FyersDataSocket","exception":"Traceback (most recent call last):\n  File \"C:\\Users\\USER\\AppData\\Local\\Programs\\Python\\Python312\\Lib\\site-packages\\fyers_apiv3\\FyersWebsocket\\data_ws.py\", line 1433, in On_message\n    self.OnMessage(message)\n  File \"c:\\Users\\USER\\AppData\\Local\\Temp\\ccd85ab7-a10f-476e-805e-c73c32ab36f2_python_scripts.zip.6f2\\python_scripts\\fyerapi.py\", line 198, in onmessage\n    timestamp = datetime.fromtimestamp(message.get(\"exch_feed_time\"))\n                ^^^^^^^^^^^^^^^^^^^^^^^^^^^^^^^^^^^^^^^^^^^^^^^^^^^^^\nTypeError: 'NoneType' object cannot be interpreted as an integer","exception_name":"TypeError"}
{"level":"ERROR","location":"[On_message:1447] data_ws","message":"'NoneType' object cannot be interpreted as an integer","timestamp":"2024-09-09 17:35:30,815+0530","service":"FyersDataSocket"}
{"level":"ERROR","location":"[symbol_to_hsmtoken:126] data_ws","message":"cannot access local variable 'hsm_symbol' where it is not associated with a value","timestamp":"2024-09-09 17:35:32,557+0530","service":"FyersDataSocket","exception":"Traceback (most recent call last):\n  File \"C:\\Users\\USER\\AppData\\Local\\Programs\\Python\\Python312\\Lib\\site-packages\\fyers_apiv3\\FyersWebsocket\\data_ws.py\", line 115, in symbol_to_hsmtoken\n    datadict[hsm_symbol] = symbol\n             ^^^^^^^^^^\nUnboundLocalError: cannot access local variable 'hsm_symbol' where it is not associated with a value","exception_name":"UnboundLocalError"}
{"level":"ERROR","location":"[__symbol_conversion:1374] data_ws","message":"'NoneType' object is not subscriptable","timestamp":"2024-09-09 17:35:32,561+0530","service":"FyersDataSocket","exception":"Traceback (most recent call last):\n  File \"C:\\Users\\USER\\AppData\\Local\\Programs\\Python\\Python312\\Lib\\site-packages\\fyers_apiv3\\FyersWebsocket\\data_ws.py\", line 1333, in __symbol_conversion\n    if symbol_value[3] != \"\":\n       ~~~~~~~~~~~~^^^\nTypeError: 'NoneType' object is not subscriptable","exception_name":"TypeError"}
{"level":"ERROR","location":"[On_message:1446] data_ws","message":"'NoneType' object cannot be interpreted as an integer","timestamp":"2024-09-09 17:38:21,365+0530","service":"FyersDataSocket","exception":"Traceback (most recent call last):\n  File \"C:\\Users\\USER\\AppData\\Local\\Programs\\Python\\Python312\\Lib\\site-packages\\fyers_apiv3\\FyersWebsocket\\data_ws.py\", line 1433, in On_message\n    self.OnMessage(message)\n  File \"c:\\Users\\USER\\AppData\\Local\\Temp\\ccd85ab7-a10f-476e-805e-c73c32ab36f2_python_scripts.zip.6f2\\python_scripts\\fyerapi.py\", line 198, in onmessage\n    timestamp = datetime.fromtimestamp(message.get(\"exch_feed_time\"))\n                ^^^^^^^^^^^^^^^^^^^^^^^^^^^^^^^^^^^^^^^^^^^^^^^^^^^^^\nTypeError: 'NoneType' object cannot be interpreted as an integer","exception_name":"TypeError"}
{"level":"ERROR","location":"[On_message:1447] data_ws","message":"'NoneType' object cannot be interpreted as an integer","timestamp":"2024-09-09 17:38:21,373+0530","service":"FyersDataSocket"}
{"level":"ERROR","location":"[symbol_to_hsmtoken:126] data_ws","message":"cannot access local variable 'hsm_symbol' where it is not associated with a value","timestamp":"2024-09-09 17:38:22,970+0530","service":"FyersDataSocket","exception":"Traceback (most recent call last):\n  File \"C:\\Users\\USER\\AppData\\Local\\Programs\\Python\\Python312\\Lib\\site-packages\\fyers_apiv3\\FyersWebsocket\\data_ws.py\", line 115, in symbol_to_hsmtoken\n    datadict[hsm_symbol] = symbol\n             ^^^^^^^^^^\nUnboundLocalError: cannot access local variable 'hsm_symbol' where it is not associated with a value","exception_name":"UnboundLocalError"}
{"level":"ERROR","location":"[__symbol_conversion:1374] data_ws","message":"'NoneType' object is not subscriptable","timestamp":"2024-09-09 17:38:22,974+0530","service":"FyersDataSocket","exception":"Traceback (most recent call last):\n  File \"C:\\Users\\USER\\AppData\\Local\\Programs\\Python\\Python312\\Lib\\site-packages\\fyers_apiv3\\FyersWebsocket\\data_ws.py\", line 1333, in __symbol_conversion\n    if symbol_value[3] != \"\":\n       ~~~~~~~~~~~~^^^\nTypeError: 'NoneType' object is not subscriptable","exception_name":"TypeError"}
{"level":"ERROR","location":"[__init_connection:1675] data_ws","message":"partially initialized module 'websocket' has no attribute 'WebSocketApp' (most likely due to a circular import)","timestamp":"2024-09-09 17:51:11,308+0530","service":"FyersDataSocket","exception":"Traceback (most recent call last):\n  File \"C:\\Users\\USER\\AppData\\Local\\Programs\\Python\\Python312\\Lib\\site-packages\\fyers_apiv3\\FyersWebsocket\\data_ws.py\", line 1660, in __init_connection\n    ws = websocket.WebSocketApp(\n         ^^^^^^^^^^^^^^^^^^^^^^\nAttributeError: partially initialized module 'websocket' has no attribute 'WebSocketApp' (most likely due to a circular import). Did you mean: 'websocket'?","exception_name":"AttributeError"}
{"level":"ERROR","location":"[__init_connection:1675] data_ws","message":"module 'websocket' has no attribute 'WebSocketApp'","timestamp":"2024-09-09 17:51:14,516+0530","service":"FyersDataSocket","exception":"Traceback (most recent call last):\n  File \"C:\\Users\\USER\\AppData\\Local\\Programs\\Python\\Python312\\Lib\\site-packages\\fyers_apiv3\\FyersWebsocket\\data_ws.py\", line 1660, in __init_connection\n    ws = websocket.WebSocketApp(\n         ^^^^^^^^^^^^^^^^^^^^^^\nAttributeError: module 'websocket' has no attribute 'WebSocketApp'. Did you mean: 'websocket'?","exception_name":"AttributeError"}
